============================= test session starts ==============================
platform linux -- Python 3.10.13, pytest-7.3.1, pluggy-1.3.0 -- /home/marcelo/wazuh/wazuh/venv-connexion/bin/python
cachedir: .pytest_cache
metadata: {'Python': '3.10.13', 'Platform': 'Linux-5.15.133.1-microsoft-standard-WSL2-x86_64-with-glibc2.31', 'Packages': {'pytest': '7.3.1', 'pluggy': '1.3.0'}, 'Plugins': {'asyncio': '0.18.1', 'trio': '0.7.0', 'tavern': '1.23.5', 'metadata': '3.0.0', 'html': '2.1.1', 'anyio': '4.0.0'}}
rootdir: /home/marcelo/wazuh/wazuh/api/test/integration
configfile: pytest.ini
plugins: asyncio-0.18.1, trio-0.7.0, tavern-1.23.5, metadata-3.0.0, html-2.1.1, anyio-4.0.0
asyncio: mode=auto
collecting ... collected 0 items / 1 error

==================================== ERRORS ====================================
____________ ERROR collecting test_agent_GET_endpoints.tavern.yaml _____________
venv-connexion/lib/python3.10/site-packages/tavern/testutils/pytesthook/file.py:325: in collect
    for i in self._generate_items(test_spec):
venv-connexion/lib/python3.10/site-packages/tavern/testutils/pytesthook/file.py:280: in _generate_items
    fmt_vars = self._get_test_fmt_vars(test_spec)
venv-connexion/lib/python3.10/site-packages/tavern/testutils/pytesthook/file.py:238: in _get_test_fmt_vars
    global_cfg = load_global_cfg(self.config)
venv-connexion/lib/python3.10/site-packages/tavern/testutils/pytesthook/util.py:135: in load_global_cfg
    global_cfg = load_global_config(all_paths)
venv-connexion/lib/python3.10/site-packages/tavern/util/general.py:27: in load_global_config
    contents = load_single_document_yaml(filename)
venv-connexion/lib/python3.10/site-packages/tavern/util/loader.py:439: in load_single_document_yaml
    with open(filename, "r", encoding="utf-8") as fileobj:
E   FileNotFoundError: [Errno 2] No such file or directory: 'common.yaml'
=============================== warnings summary ===============================
venv-connexion/lib/python3.10/site-packages/_pytest/nodes.py:642
  /home/marcelo/wazuh/wazuh/venv-connexion/lib/python3.10/site-packages/_pytest/nodes.py:642: PytestRemovedIn8Warning: The (fspath: py.path.local) argument to YamlFile is deprecated. Please use the (path: pathlib.Path) argument instead.
  See https://docs.pytest.org/en/latest/deprecations.html#fspath-argument-for-node-constructors-replaced-with-pathlib-path
    return super().from_parent(parent=parent, fspath=fspath, path=path, **kw)

venv-connexion/lib/python3.10/site-packages/pytest_trio/plugin.py:62
  /home/marcelo/wazuh/wazuh/venv-connexion/lib/python3.10/site-packages/pytest_trio/plugin.py:62: TrioDeprecationWarning: trio.MultiError is deprecated since Trio 0.22.0; use BaseExceptionGroup (on Python 3.11 and later) or exceptiongroup.BaseExceptionGroup (earlier versions) instead (https://github.com/python-trio/trio/issues/2211)
    if issubclass(call.excinfo.type, trio.MultiError):

-- Docs: https://docs.pytest.org/en/stable/how-to/capture-warnings.html
=========================== short test summary info ============================
ERROR api/test/integration/test_agent_GET_endpoints.tavern.yaml - FileNotFoun...
!!!!!!!!!!!!!!!!!!!! Interrupted: 1 error during collection !!!!!!!!!!!!!!!!!!!!
========================= 2 warnings, 1 error in 0.37s =========================
